# 异常
异常就是,当 Go 检测到了一个错误,程序就无法执行了,反而出现一些错误提示,这就是所谓的异常
```go
fun test(a,b int) int {
	var result int 
	result = a / b
	return result
}
```
> 上面的代码中,只是简单的计算两个值相除,但是如果传递 b 的值为0,那么程序就会报错 division by zero ,并且整个程序会停止运行,那么如果出现这种问题的话,应该怎么处理呢?这就需要使用到异常处理方法的内容

异常主要分为三种情况:
- 编辑时异常: 代码在书写的时候有错误

- 编译时异常:代码在运行之前需要编译成可执行程序,在这个阶段出现的异常

- 运行时异常:程序能正常编译,但是运行的时候出错,或者是运行结果与预期不同

## error接口
Go 语言总引入了一个错误处理的标准模式,即error接口,它是 Go 语言内建的接口类型,Go 语言的标准库代码包errors 为用户提供如下方法:
```go
package errors

// New返回一个错误，该错误的格式为给定文本
// 即使文本相同，每次对New的调用也会返回一个不同的错误值。
func New(text string) error {
	return &errorString{text}
}

// errorString是错误的简单实现
type errorString struct {
	s string
}

func (e *errorString) Error() string {
	return e.s
}
```

通过上面的代码,可以发现 error 接口的使用方法非常简单(error 是一个接口,该接口只声明了一个方法 Error(),返回值是 string 类型,用以描述错误),下面是基本的使用方法

1. 首先要导入相应的包
```go
import "errors"
```

2. 调用其方法
```go
package main

import (
	"errors"
	"fmt"
)

func test(a,b float64) (result float64,err error)  {
	// 如果 除数为0,返回result为默认值,err 为制定的字符串,如果除数不为0 ,返回result 为结果,err 为空
	if b==0{
		err = errors.New("b 是一个错误的值")
	}else {
		result = a/b
	}
	return
}

func main()  {
	value , err := test(3,0)
	// 判断 err是否为空,如果为空说明除数为0
	if err != nil {
		fmt.Println(err)
	}else {
		fmt.Println(value)
	}
}
```

- fmt 中也封装了一个专门针对输出错误信息的放方法 fmt.Errorf ,上面的代码也可以更改
```go
package main

import (
	"fmt"
)

func test(a,b float64) (result float64,err error)  {
	if b==0{
		err = fmt.Errorf("%s","这是一个错误的值")
	}else {
		result = a/b
	}
	return
}

func main()  {
	value , err := test(3,0)
	if err != nil {
		fmt.Println(err)
	}else {
		fmt.Println(value)
	}
}
```

## panic 函数
error 返回的是一般性的错误,但是 panic 函数返回的是使程序奔溃的错误.

也就是当遇到不可恢复的错误状态的时候,如数组访问越界、空指针引用等,这些错误运行时会引起 panic 异常,在一般情况下,我们不应该通过调用 panic 函数来报告普通的错误,而应该只把它作为报告致命错误的一种方式,当某些不应该发生的场景发生时,我们就应该调用 panic.

一般而言, 当 panic异常发生时, 程序会中断运行,随后,程序奔溃并输出日志信息,日志信息包括 panic value和函数调用的堆栈跟踪信息
```go
package main

import "fmt"

func main()  {
	var arr []int

	fmt.Println(arr[0]) // 调用空指针
}
```
报错信息如下
```go
panic: runtime error: index out of range [0] with length 0

goroutine 1 [running]:
main.main()
        /Users/weiying/go/test.go:8 +0x18

Process finished with exit code 2
```
当然如果直接调用内置的 panic 函数也会引发 panic 异常, panic 函数接受任何值作为参数
```go
package main

import "fmt"

func main()  {
	var arr int
	fmt.Println("arr",arr)
	panic("这是 panic 异常") // 直接调用 panic ,参数是空接口类型,支持任意类型的参数
	// 遇到 panic 直接会终止程序执行,并根据 panic 函数中制定的参数,返回
	fmt.Println("arr",arr)
}
```
报错信息如下
```go
arr 0 // 输出第一个没问题
panic: 这是 panic 异常

goroutine 1 [running]:
main.main()
        /Users/weiying/go/test.go:8 +0xbd

Process finished with exit code 2
```
> 所以我们在实际的开发过程中并不会直接调用panic函数,因为当程序执行的说话遇到了致命错误,系统会自动的调用该函数来终止程序,也就是系统中内置了panic函数

## defer 延迟调用
函数定义完成之后,只有被调用了才会执行,并且一经调用就会立即执行,例如
```go
fmt.println("hello")
fmt.println("world")
```
会先输出hello在输出world

但是关键词 defer 用于延迟一个函数(或者是当前所创建的匿名函数)的执行

> 注意:defer语句只能出现在函数的内部
```go
	defer fmt.Println("hello")
	fmt.Println("world")
```
加上defer关键词后,defer所在的行的代码就会在函数的最后执行

> defer 调用函数的时候,并没有直接调用,而是先加载到内存中,在函数结束时进行调用,符合出栈的规则(先入后出)

1. 多个 defer 语句的执行顺序
```go
func main()  {
	defer fmt.Println("hello")
	defer fmt.Println("world")
	defer fmt.Println("aaa")
}
```
输出结果为:先输出 aaa ,再输出 world ,最后输出hello

2. 当 defer 遇到异常
```go
package main

import (
	"fmt"
)

func test(x int)  {
	re := 10/x
	fmt.Println(re)
}

func main()  {

	defer fmt.Println("hello")

	defer fmt.Println("world")
	defer test(0)
	defer fmt.Println("aaa")
}
```
输出结果
```go
aaa
world
hello
panic: runtime error: integer divide by zero
```
> 即使函数或者某个延迟调用发生错误,这些调用依旧会被执行

3. defer 与匿名函数结合
```go
package main

import "fmt"

func main()  {

	a := 10
	b := 20
	defer func() {
		fmt.Println("匿名函数中的a：",a)
		fmt.Println("匿名函数中的b：",b)
	}()

	a = 100
	b = 200
	fmt.Println("main函数中的a：",a)
	fmt.Println("main函数中的b：",b)
}
// 输出的结果为
main函数中的a： 100
main函数中的b： 200
匿名函数中的a： 100
匿名函数中的b： 200
```
> defer 函数能延迟函数的执行,虽然调用了匿名函数,但是,该匿名函数不会去执行,而是等整个main函数执行结束之前去执行

将上面的代码进行修改
```go
package main

import "fmt"

func main()  {

	a := 10
	b := 20
	defer func(a,b int) {
		fmt.Println("匿名函数中的a：",a)
		fmt.Println("匿名函数中的b：",b)
	}(a,b)

	a = 100
	b = 200
	fmt.Println("main函数中的a：",a)
	fmt.Println("main函数中的b：",b)
}
//执行结果
main函数中的a： 100
main函数中的b： 200
匿名函数中的a： 10
匿名函数中的b： 20
```
> 通过执行结果我们可以看出,虽然匿名函数被延迟调用了,但是已经在延迟之前完成和参数的传递

思考下面代码的结果
```go
package main

import "fmt"

func test1(x int) int {
	return x + x
}

func test2(a int) (r int)  {
	defer func() {
		r += a
	}()
	return test1(a)
}

func main()  {
	fmt.Println(test2(3))
}
```

> 分析:首先给test2()函数传递的值为a=3,test2()中的匿名函数延迟执行,执行test1(3),得到的结果为6,也就是return 6,即 r=6,执行匿名函数的得到 r = 9,最终的结果为r = 9

## recover
运行是 panic 异常一旦被引发,那么就会导致程序的崩溃,这当然是我们不想看到的,因为谁也不能保证程序不会发生任何运行时错误, Go 语言为我们提供了专用于“拦截”运行时 panic 的内建函数 - - - recover , 它可以使当前程序从运行时 panic 的状态中恢复并重新获得流程控制权

如果在 defer 函数中调用了内的函数 recover,并且定义该 defer 语句的函数发生了 panic 异常,recover 会使程序从 panic 中恢复,并返回 panic vlaue,导致 panic 异常的函数不会继续执行,但是能正常返回,在未发生 panic 时调用 recover ,recover 会返回 nil

```go
package main

import "fmt"

func test1()  {
	fmt.Println("test1")
}

func test2(x int)  {
	var arr [10]int
	defer func() {
		recover() // 拦截panic异常
	}()
	arr[x] = 111
	fmt.Println(arr[x])
}

func test3()  {
	fmt.Println("test3")
}

func main()  {
	test1()
	test2(11)
	test3()
}
```
- 上面代码的输出为:test1和test3,并没有输出test2函数的内容,因为在传递参数的时候,造成了数组下标越界,正常来说,程序执行到test2函数调用的时候,就会报出 panic 异常,然后退出程序,并不会输出test3,但是当我们使用了 recover 以后,可以拦截 panic 异常,并使程序继续执行

> 注意: recover 必须使用在 defer 调用的函数中才能生效

上面的代码中,程序虽然没有崩溃退出,但是也没有提示任何错误信息,我们对上面的代码进行修改
```go
package main

import "fmt"

func test1()  {
	fmt.Println("test1")
}

func test2(x int)  {
	var arr [10]int
	defer func() {
		fmt.Println(recover()) // 打印 panic 异常的信息
	}()
	arr[x] = 111
	fmt.Println(arr[x])
}

func test3()  {
	fmt.Println("test3")
}

func main()  {
	test1()
	test2(11)
	test3()
}
```
上面的代码的输出为
```go
test1
runtime error: index out of range [11] with length 10
test3
```

> recover 中存储的是 panic 异常的信息,如果没有出现 panic 异常,那么 recover 存储为空,因此可以通过 recover 是否为空,来判断是否出现 panic 异常

```go
package main

import "fmt"

func test1()  {
	fmt.Println("test1")
}

func test2(x int)  {
	var arr [10]int
	defer func() {
		if err := recover(); err != nil{ // 对是否出现 panic 异常进行判断
			fmt.Println(err)
		}
	}() // 此处的括号一定要添加,保证匿名函数会被调用
	arr[x] = 111
	fmt.Println(arr[x])
}

func test3()  {
	fmt.Println("test3")
}

func main()  {
	test1()
	test2(11)
	test3()
}
```

>  recover 拦截异常,必须是出现在 panic 异常之前,而不是能是异常已经发生了,一旦拦截到了 panic 异常的代码,之后的代码便不会执行